Workbook

Sheet New_6 Factors Form
A1: Thai Parkerizing Co., Ltd. | AU1: E7 | AV1: T | AW1: =AU1&AV1 -> E7T | AX1: =VLOOKUP($AW$1,'Weight & Grade Def.'!$G$7:$I$86,2,0) -> E6T | AY1: =VLOOKUP($AW$1,'Weight & Grade Def.'!$G$7:$I$86,3,0) -> E8T
A2: Behavioral Appraisal - Competency Assessment Form | AX2: =VLOOKUP($AW$1,'Weight & Grade Def.'!$G$7:$I$86,2,0) -> E6T | AY2: =VLOOKUP($AW$1,'Weight & Grade Def.'!$G$7:$I$86,2,0) -> E6T
AK3: Our signatures indicates mutual agreement on the below professOur signatures indicates mutual agreement on the below professionality assessment, comments, and training & development planionality assessment, comments, and training & development plan การลงลายมือชื่อของเรา แสดงถึง ความเข้าใจและเห็นพ้องต้องกันในผลการประเมิน การให้คำติชม รวมถึงการดำเนินการเรื่องแผนการพัฒนาและการฝึกอบรมที่อยู่ด้านล่างนี้ | AO3: 1st-Half Assessment for Mid-Year Bonus
A4: Name | I4: Code | M4: Position | V4: Current Grade | X4: =AU1 -> E7 | AB4: Date promoted to current grade | AX4: Upper | AY4: Lower
A5: ชื่อ-นามสกุล | I5: รหัสพนักงาน | M5: ตำแหน่ง | V5: เกรดปัจจุบัน | AB5: วันที่ได้รับการปรับสู่เกรดปัจจุบัน
AO6: Appraisee | AQ6: 1st Appraiser | AS6: 2nd Appraiser
A7: Location | H7: Division / Department / Section | Y7: Date joined | AE7: Total year-of-service | AJ7: Years | AO7: Date: | AQ7: Date: | AS7: Date:
A8: พื้นที่ปฏิบัติงาน | H8: ฝ่าย / แผนก / หน่วยงาน | Y8: วันเริ่มงาน | AE8: อายุงาน | AO8: 2nd-Half Assessment for Year-End Bonus
A10: First Appraiser | O10: Second Appraiser | AE10: Appraisal Period
A11: (ระบุชื่อและตำแหน่งของผู้ประเมินคนที่ 1) | O11: (ระบุชื่อและตำแหน่งของผู้ประเมินคนที่ 2) | AE11: ช่วงการประเมิน | AO11: Appraisee | AQ11: 1st Appraiser | AS11: 2nd Appraiser
AO12: Date: | AQ12: Date: | AS12: Date:
A14: Grade Definition คำนิยาม | C14: Upper Grade เกรดที่สูงกว่า | F14: =VLOOKUP($F$16,'Weight & Grade Def.'!$B$7:$D$46,2,0) -> E6 | G14: =IFERROR(VLOOKUP($AX$1,'Weight & Grade Def.'!$G$6:$N$86,8,0),"-") -> จัดการกับงานสำคัญที่ได้รับมอบหมายตามขอบเขตงานให้สำเร็จลุล่วงได้โดยลำพัง ; ปรับเปลี่ยน หรือ ตรวจสอบ พร้อมทั้งแก้ไขปัญหาในระบบปฏิบัติการ หรือ กระบวนการทำงานที่มีอยู่ ณ ปัจจุบัน ; แก้ไขปัญหาในการปฏิบัติงานด้วยอำนาจที่มีอยู่อย่างจำกัด เพื่อจัดการทรัพยากรการดำเนินงานในขอบเขตที่ได้รับมอบหมาย ; โน้มน้าวหรืออธิบายข้อเท็จจริง แนวปฏิบัติ นโยบาย ต่อบุคคลที่เกี่ยวข้องทั้งภายในและภายนอก ; สอนความรู้ในงานให้แก่ระดับที่ต่ำกว่า ; มีความรู้ระดับก้าวหน้าในขอบเขตงานหนึ่ง | AJ14: Measuring Criteria : เงื่อนไขการประเมิน
AJ15: 5: | AK15: Always take appropriate action and be regarded as a "role model" ดำเนินการได้อย่างเหมาะสม ตรงตามที่คาดหวังอยู่เสมอ และได้รับการยอมรับในฐานะแบบอย่างที่ดี
C16: Current Grade เกรดปัจจุบัน | F16: =AU1 -> E7 | G16: =IFERROR(VLOOKUP($AW$1,'Weight & Grade Def.'!$G$6:$N$86,8,0),"-") -> จัดการกับงานที่ได้รับมอบหมายตามขอบเขตงานให้สำเร็จลุล่วงภายใต้การกำกับดูแลที่จำกัด ; ตรวจสอบ และ แก้ไขปัญหาในระบบปฏิบัติการ หรือ กระบวนการทำงานที่มีอยู่ ณ ปัจจุบัน ; แก้ไขปัญหาในงานที่มีการระบุไว้แล้วอย่างชัดเจนในขอบเขตที่ได้รับมอบหมาย ; อธิบายเกี่ยวกับข้อเท็จจริง แนวปฏิบัติ นโยบายแก่้ผู้มีส่วนเกี่ยวข้องหลักภายในได้ ; ให้คำชี้แนะเกี่ยวกับความรู้ในงานแก่ระดับที่ต่ำกว่า ; มีความรู้เกี่ยวกับงานในเชิงปฏิบัติในขอบเขตงานหนึ่ง | AJ16: 4: | AK16: Always take appropriate action in various situations ดำเนินการได้อย่างเหมาะสม ตรงตามที่คาดหวัง ในหลากหลายสถานการณ์
AJ17: 3: | AK17: Take appropriate action as expected ดำเนินการได้อย่างเหมาะสม ตรงตามที่คาดหวัง
C18: Lower Grade เกรดที่ต่ำกว่า | F18: =VLOOKUP($F$16,'Weight & Grade Def.'!$B$7:$D$46,3,0) -> E8 | G18: =IFERROR(VLOOKUP($AY$1,'Weight & Grade Def.'!$G$6:$N$86,8,0),"-") -> จัดการกับงานระดับพื้นฐานที่ได้รับมอบหมายตามขอบเขตงานให้สำเร็จลุล่วงภายใต้การกำกับดูแลทั่วไป ; ตรวจสอบระบบปฏิบัติการ หรือ กระบวนการทำงานที่มีอยู่ ณ ปัจจุบัน ; แก้ไขปัญหาในงานที่มีการระบุไว้แล้วอย่างชัดเจนในขอบเขตที่ได้รับมอบหมาย ; อธิบายเกี่ยวกับข้อเท็จจริง แนวการปฏิบัติ นโยบายแก่้ผู้มีส่วนเกี่ยวข้องหลักภายในได้ ; ให้คำชี้แนะเกี่ยวกับความรู้ในงานแก่ระดับที่ต่ำกว่า ; มีความรู้เกี่ยวกับงานในเชิงทฤษฎีในขอบเขตงานหนึ่ง | AJ18: 2: | AK18: Take some action but not fully appropriate มีการดำเนินการบ้าง แต่ไม่ได้ถูกต้องและเหมาะสมไปทั้งหมด
AJ19: 1: | AK19: No action taking at all ไม่ดำเนินการสิ่งใดเลย
A21: Behavioral Assessment
A23: Items (หัวข้อ) | C23: Definition (คำนิยาม) | G23: Viewpoint (พฤติกรรมตามตำแหน่ง) | K23: 1st-Half Assessment for Mid-Year Bonus (การประเมินผลช่วงครึ่งปีแรก ม.ค. ถึง มิ.ย. เพื่อจ่ายโบนัสกลางปี) | AC23: 2nd-Half Assessment for Year-End Bonus (การประเมินผลช่วงครึ่งปีหลัง ก.ค. ถึง ธ.ค. เพื่อจ่ายโบนัสปลายปี)
K24: Self-Assessment () | Q24: 1st Appraisal Assessment () | W24: 2nd Appraisal Assessment () | AC24: Self-Assessment () | AI24: 1st Appraisal Assessment () | AO24: 2nd Appraisal Assessment ()
K25: Score | L25: Comment / Reason (if any) | Q25: Score | R25: Comment / Reason (if any) | W25: Score | X25: Comment / Reason (if any) | AC25: Score | AD25: Comment / Reason (if any) | AI25: Score | AJ25: Comment / Reason (if any) | AO25: Score | AP25: Comment / Reason (if any)
K26: คะแนน | L26: คำติชม/ เหตุผล (ถ้ามี) | Q26: คะแนน | R26: คำติชม/ เหตุผล (ถ้ามี) | W26: คะแนน | X26: คำติชม/ เหตุผล (ถ้ามี) | AC26: คะแนน | AD26: คำติชม/ เหตุผล (ถ้ามี) | AI26: คะแนน | AJ26: คำติชม/ เหตุผล (ถ้ามี) | AO26: คะแนน | AP26: คำติชม/ เหตุผล (ถ้ามี)
A27: Managing Self การจัดการตนเอง | C27: =VLOOKUP($AW$1,'6 Factors Definition'!$B$3:$O$84,2,0) -> นำความรู้และทักษะไปใช้อย่างมีประสิทธิภาพ พัฒนาตนเองในลักษณะของการเพิ่มพูนประสิทธิภาพในบทบาทและหน้าที่ที่รับผิดชอบ และแสดงให้เห็นถึงการพัฒนาตนเองอย่างต่อเนื่องในฐานะผู้ปฏิบัติงานที่มีประสบการณ์ | G27: =VLOOKUP($AW$1,'6 Factors Definition'!$B$3:$O$84,9,0) -> - รู้จักบทบาทที่คาดหวังและแสดงความรับผิดชอบตามที่คาดไว้ - ดำเนินการให้ได้มาซึ่งความรู้ ทักษะ และความเชี่ยวชาญใหม่ ๆ | K27: 5 | Q27: 5 | W27: 5 | AC27: 5 | AI27: 5 | AO27: 5
A33: Managing Others การจัดการผู้อื่น | C33: =VLOOKUP($AW$1,'6 Factors Definition'!$B$3:$O$84,3,0) -> ทำงานร่วมกับผู้อื่นได้อย่างมีประสิทธิภาพ รวมถึงสามารถสื่อสารเพื่อจูงใจและโน้มน้าวผู้อื่นได้อย่างเหมาะสมในฐานะผู้ปฏิบัติงาน | G33: =VLOOKUP($AW$1,'6 Factors Definition'!$B$3:$O$84,10,0) -> - ทำงานร่วมกับผู้อื่นเพื่อบรรลุเป้าหมายร่วมได้ - สื่อสาร และ โน้มน้าวผู้อื่นได้อย่างมีประสิทธิภาพ | K33: 5 | Q33: 5 | W33: 5 | AC33: 5 | AI33: 5 | AO33: 5
A39: Managing Problem การจัดการปัญหา | C39: =VLOOKUP($AW$1,'6 Factors Definition'!$B$3:$O$84,4,0) -> คิดวิเคราะห์ เพื่อระบุปัญหา พร้อมกับพิจารณาทางเลือก และพัฒนาวิธีการแก้ปัญหาในงานที่ตนเองได้รับมอบหมาย | G39: =VLOOKUP($AW$1,'6 Factors Definition'!$B$3:$O$84,11,0) -> - คิดเชิงวิเคราะห์เพื่อระบุปัญหา และวิธีการแก้ไข - ตัดสินใจ ภายใต้ขอบเขตของอำนาจที่ได้รับมอบหมาย และลงมือแก้ไขปัญหาตามเวลาที่กำหนด | K39: 5 | Q39: 5 | W39: 5 | AC39: 5 | AI39: 5 | AO39: 5
A45: Managing Performance การจัดการ ผลการปฏิบัติงาน | C45: =VLOOKUP($AW$1,'6 Factors Definition'!$B$3:$O$84,5,0) -> นำตนเอง และ จัดการกับงานเพื่อบรรลุเป้าหมายที่กำหนดไว้ หรือ ดำเนินงานที่ได้รับมอบหมายให้แล้วเสร็จ | G45: =VLOOKUP($AW$1,'6 Factors Definition'!$B$3:$O$84,12,0) -> - วางแผน, จัดลำดับความสำคัญ, จัดการกับทรัพยากรที่มีอยู่ และสร้างกระบวนการทำงานที่ดีที่สุดเพื่อบรรลุเป้าหมายร่วม - นำตนเอง และผู้อื่นมุ่งสู่การบรรลุเป้าหมายร่วม | K45: 5 | Q45: 5 | W45: 5 | AC45: 5 | AI45: 5 | AO45: 5
A51: Managing Improvement การจัดการเรื่อง การปรับปรุงงาน | C51: =VLOOKUP($AW$1,'6 Factors Definition'!$B$3:$O$84,6,0) -> ปรับปรุงงานที่ตนเองเป็นผู้ได้รับมอบหมายโดยตรง โดยการชี้บ่งวิธีการปรับปรุง หรือ พัฒนาแนวทางใหม่ๆ เพื่อมุ่งไปข้างหน้า | G51: =VLOOKUP($AW$1,'6 Factors Definition'!$B$3:$O$84,13,0) -> - สร้างแนวคิด หรือ ส่งเสริมผู้อื่นให้ดำเนินการเรื่องการปรับปรุงงาน - นำแนวคิดไปลงมือปฏิบัติอย่างเป็นรูปธรรม | K51: 5 | Q51: 5 | W51: 5 | AC51: 5 | AI51: 5 | AO51: 5
A57: Managing Risk การจัดการความเสี่ยง | C57: =VLOOKUP($AW$1,'6 Factors Definition'!$B$3:$O$84,7,0) -> ลดความเสี่ยงในกระบวนการปฏิบัติงาน โดยปรับเปลี่ยนให้สอดคล้องกับกฎระเบียบ แนวปฏิบัติ และมาตรฐานในการปฏิบัติงานของบริษัทฯ รวมไปถึงการกำหนดมาตรการป้องกัน | G57: =VLOOKUP($AW$1,'6 Factors Definition'!$B$3:$O$84,14,0) -> - ปฏิบัติตนสอดคล้องกับกฎระเบียบ และมาตรฐานการปฏิบัติงานเพื่อให้เกิดคุณภาพ - ระบุความเสี่ยงในงาน และกำหนดมาตรการป้องกัน | K57: 5 | Q57: 5 | W57: 5 | AC57: 5 | AI57: 5 | AO57: 5
J63: Average | K63: =AVERAGE(K27:K62) -> 5 | Q63: =AVERAGE(Q27:Q62) -> 5 | W63: =AVERAGE(W27:W62) -> 5 | AC63: =AVERAGE(AC27:AC62) -> 5 | AI63: =AVERAGE(AI27:AI62) -> 5 | AO63: =AVERAGE(AO27:AO62) -> 5
A65: Additional Remarks (หมายเหตุเพิ่มเติม)
A66: 1st-Half Assessment : การประเมินช่วงครึ่งปีแรก | F66: 2nd-Half Assessment:การประเมินช่วงครึ่งปีหลัง | L66: 1st-Half Assessment for Mid-Year Bonus (การประเมินผลช่วงครึ่งปีแรก ม.ค. ถึง มิ.ย. เพื่อจ่ายโบนัสกลางปี) | AD66: 2nd-Half Assessment for Year-End Bonus (การประเมินผลช่วงครึ่งปีหลัง ก.ค. ถึง ธ.ค. เพื่อจ่ายโบนัสปลายปี)
A67: 1st Appraiser | F67: 1st Appraiser | L67: Overall Appraisal Rating | Q67: Rating | T67: Weight | W67: Score | Z67: Appraisal Rating | AD67: Overall Appraisal Rating | AI67: Rating | AL67: Weight | AO67: Score | AR67: Appraisal Rating
L68: รวมผลการประเมินทั้งหมด | Q68: ผลคะแนน | T68: น้ำหนัก | W68: คะแนน | Z68: สรุปผลการประเมิน | AD68: รวมผลการประเมินทั้งหมด | AI68: ผลคะแนน | AL68: น้ำหนัก | AO68: คะแนน | AR68: สรุปผลการประเมิน
L69: Performance / Goals (MBO) | Q69: =ROUND('New_MBO Form'!$Y$115,1) -> 0 | T69: =VLOOKUP($AU$1,'Weight & Grade Def.'!$B$7:$M$46,9,0) -> 30 | W69: =(Q69*T69)/100 -> 0 | Z69: =W69+W71 -> 3.5 | AD69: Performance / Goals (MBO) | AI69: =ROUND('New_MBO Form'!$AS$115,1) -> 0 | AL69: =VLOOKUP($AU$1,'Weight & Grade Def.'!$B$7:$M$46,9,0) -> 30 | AO69: =(AI69*AL69)/100 -> 0 | AR69: =AO69+AO71 -> 3.5
A70: 2nd Appraiser | F70: 2nd Appraiser | L70: ผลงาน / การบรรลุเป้าหมาย | AD70: ผลงาน / การบรรลุเป้าหมาย
L71: Behavioral (6 Factors) | Q71: =ROUND(W63,1) -> 5 | T71: =VLOOKUP($AU$1,'Weight & Grade Def.'!$B$7:$M$46,12,0) -> 70 | W71: =(Q71*T71)/100 -> 3.5 | AD71: Behavioral (6 Factors) | AI71: =ROUND(AO63,1) -> 5 | AL71: =VLOOKUP($AU$1,'Weight & Grade Def.'!$B$7:$M$46,12,0) -> 70 | AO71: =(AI71*AL71)/100 -> 3.5
L72: พฤติกรรม | AD72: พฤติกรรม
A74: [For 1st Appraiser] Discussion for further development, only for 2nd half - Evaluation | R74: [For 1st Appraiser and HR] Training and Development Plan, only for 2nd half-evaluation
A75: [ สำหรับผู้ประเมินคนที่ 1] พูดคุยกับผู้ถูกประเมินเกี่ยวกับการพัฒนาในอนาคต, ดำเนินการ เฉพาะในการประเมินช่วงครึ่งปีหลังเท่านัน | R75: [ สำหรับผู้ประเมินคนที่ 1 กับ หน่วยงาน HR] กำหนดแผนการอบรมและพัฒนา, ดำเนินการเฉพาะในการประเมินช่วงครึ่งปีหลังเท่านั้น
A77: Strengths (จุดแข็ง สิ่งที่ทำได้ดี) | I77: Development Needs (สิ่งที่ต้องการจะปรับปรุง) | R77: Training & Development Plan : แผนการอบรม และ พัฒนา | AD77: Training & Development Methods (วิธีการอบรมและพัฒนา) | AM77: Responsible by (ผู้รับผิดชอบ) | AQ77: Target Started & Achieved time
...

Sheet 6 Factors Definition
B1: 1 | C1: 2 | D1: 3 | E1: 4 | F1: 5 | G1: 6 | H1: 7 | I1: 8 | J1: 9 | K1: 10 | L1: 11 | M1: 12 | N1: 13 | O1: 14
C2: Definition | J2: View Point
A3: No. | B3: Grade | C3: Managing Self | D3: Managing Others | E3: Managing Problem | F3: Managing Performance | G3: Managing Improvement | H3: Managing Risk | J3: Managing Self | K3: Managing Others | L3: Managing Problem | M3: Managing Performance | N3: Managing Improvement | O3: Managing Risk
A4: 1 | B4: M1E | C4: Effectively utilizing knowledge/skills and manage oneself in a manner that enhances role effectiveness and demonstrate continuous self development as management | D4: Effectively co-operate and properly communicate with others to achieve company goals | E4: Identify, analyze issue, consider options and develop solutions to correct problem in company | F4: Lead/ manage team performance to achieve resposible scope | G4: lmprove overall performance on responsible scope and encourage others to do so by identifying and/or developing a new way forward | H4: Minimize complex risk in entire company by complying to organization's rules, practice and work standard, together with,taking preventive action | J4: - Know expected role and show responsibility as expected - Continue to acquire new knowledge, skills and expertise - Able to develop strategy and plan to drive business | K4: - Work collaboratively towards common goals - Communicate and influence effectively - Plan, inspire, coach and develop team capability | L4: - Think analytically to identify issue and solution - Make decision and implement solution over issues timely - Effectively optimize resource of department | M4: - Plan, prioritize, organize available resource and optimize process to achieve common goals - Lead self and others in achieving common goals - Inspire others as department to achieve company outcome | N4: - Generate ideas or encourage others to improve - Take action in implementing new ideas - Provide knowledge or training to others | O4: - Comply to rules and quality work standard - Identify operational risk and make prevention - Promote and monitor others in department to follow work standard, rule
A5: 2 | B5: M2E | C5: Effectively utilizing knowledge/skills and manage oneself in a manner that enhances role effectiveness and demonstrate continuous self development as management | D5: Effectively co-operate and properly communicate with others to achieve division goals | E5: Identify, analyze issue, consider options and develop solutions to correct problem in division | F5: Lead/ manage team performance to achieve resposible scope | G5: lmprove overall performance on responsible scope and encourage others to do so by identifying and/or developing a new way forward | H5: Minimize complex risk in division by complying to organization's rules, practice and work standard, together with,taking preventive action | J5: - Know expected role and show responsibility as expected - Continue to acquire new knowledge, skills and expertise - Able to develop strategy and plan to drive business | K5: - Work collaboratively towards common goals - Communicate and influence effectively - Plan, inspire, coach and develop team capability | L5: - Think analytically to identify issue and solution - Make decision and implement solution over issues timely - Effectively optimize resource of department | M5: - Plan, prioritize, organize available resource and optimize process to achieve common goals - Lead self and others in achieving common goals - Inspire others as department to achieve company outcome | N5: - Generate ideas or encourage others to improve - Take action in implementing new ideas - Provide knowledge or training to others | O5: - Comply to rules and quality work standard - Identify operational risk and make prevention - Promote and monitor others in department to follow work standard, rule
A6: 3 | B6: E2E | C6: Effectively utilizing knowledge/skills and manage oneself in a manner that enhances role effectiveness and demonstrate continuous self development as specialist | D6: Effectively co-operate and properly communicate with others in responsible scope | E6: Identify, analyze issue, consider options and develop solutions to critical business process | F6: Lead/ manage team performance to drive performance in responsible scope | G6: lmprove overall performance on responsible scope and encourage others to do so by identifying and/or developing a new way forward | H6: Minimize complex risk by complying to organization's rules, practice and work standard, together with,taking preventive action | J6: - Know expected role and show responsibility as expected - Continue to acquire new knowledge, skills and expertise - Able to develop strategy and plan to drive business | K6: - Work collaboratively towards common goals - Communicate and influence effectively - Plan, inspire, coach and develop team capability | L6: - Think analytically to identify issue and solution - Make decision and implement solution over issues timely - Effectively optimize resource of department | M6: - Plan, prioritize, organize available resource and optimize process to achieve common goals - Lead self and others in achieving common goals - Inspire others as department to achieve company outcome | N6: - Generate ideas or encourage others to improve - Take action in implementing new ideas - Provide knowledge or training to others | O6: - Comply to rules and quality work standard - Identify operational risk and make prevention - Promote and monitor others in department to follow work standard, rule
A7: 4 | B7: S2E | C7: Effectively utilizing knowledge/skills and manage oneself in a manner that enhances role effectiveness and demonstrate continuous self development as specialist | D7: Effectively co-operate and properly communicate with others in responsible scope | E7: Identify, analyze issue, consider options and develop solutions to critical business process | F7: Lead/ manage team performance to drive performance in responsible scope | G7: lmprove overall performance on responsible scope and encourage others to do so by identifying and/or developing a new way forward | H7: Minimize complex risk by complying to organization's rules, practice and work standard, together with,taking preventive action | J7: - Know expected role and show responsibility as expected - Continue to acquire new knowledge, skills and expertise - Able to develop strategy and plan to drive business | K7: - Work collaboratively towards common goals - Communicate and influence effectively - Plan, inspire, coach and develop team capability | L7: - Think analytically to identify issue and solution - Make decision and implement solution over issues timely - Effectively optimize resource of department | M7: - Plan, prioritize, organize available resource and optimize process to achieve common goals - Lead self and others in achieving common goals - Inspire others as department to achieve company outcome | N7: - Generate ideas or encourage others to improve - Take action in implementing new ideas - Provide knowledge or training to others | O7: - Comply to rules and quality work standard - Identify operational risk and make prevention - Promote and monitor others in department to follow work standard, rule
A8: 5 | B8: G2E | C8: Effectively utilizing knowledge/skills and manage oneself in a manner that enhances role effectiveness and demonstrate continuous self development as specialist | D8: Effectively co-operate and properly communicate with others in responsible scope | E8: Identify, analyze issue, consider options and develop solutions to critical business process | F8: Lead/ manage team performance to drive performance in responsible scope | G8: lmprove overall performance on responsible scope and encourage others to do so by identifying and/or developing a new way forward | H8: Minimize complex risk by complying to organization's rules, practice and work standard, together with,taking preventive action | J8: - Know expected role and show responsibility as expected - Continue to acquire new knowledge, skills and expertise - Able to develop strategy and plan to drive business | K8: - Work collaboratively towards common goals - Communicate and influence effectively - Plan, inspire, coach and develop team capability | L8: - Think analytically to identify issue and solution - Make decision and implement solution over issues timely - Effectively optimize resource of department | M8: - Plan, prioritize, organize available resource and optimize process to achieve common goals - Lead self and others in achieving common goals - Inspire others as department to achieve company outcome | N8: - Generate ideas or encourage others to improve - Take action in implementing new ideas - Provide knowledge or training to others | O8: - Comply to rules and quality work standard - Identify operational risk and make prevention - Promote and monitor others in department to follow work standard, rule
A9: 6 | B9: M3E | C9: Effectively utilizing knowledge/skills and manage oneself in a manner that enhances role effectiveness and demonstrate continuous self development as management | D9: Effectively co-operate and properly communicate with others to achieve departments / factory goals | E9: Identify, analyze issue, consider options and develop solutions to correct problem in departments / factory | F9: Lead/ manage team performance to achieve resposible scope | G9: lmprove overall performance on responsible scope and encourage others to do so by identifying and/or developing a new way forward | H9: Minimize complex risk in departments / factory by complying to organization's rules, practice and work standard, together with,taking preventive action | J9: - Know expected role and show responsibility as expected - Continue to acquire new knowledge, skills and expertise - Able to develop strategy and plan to drive business | K9: - Work collaboratively towards common goals - Communicate and influence effectively - Plan, inspire, coach and develop team capability | L9: - Think analytically to identify issue and solution - Make decision and implement solution over issues timely - Effectively optimize resource of department | M9: - Plan, prioritize, organize available resource and optimize process to achieve common goals - Lead self and others in achieving common goals - Inspire others as department to achieve company outcome | N9: - Generate ideas or encourage others to improve - Take action in implementing new ideas - Provide knowledge or training to others | O9: - Comply to rules and quality work standard - Identify operational risk and make prevention - Promote and monitor others in department to follow work standard, rule
A10: 7 | B10: E3E | C10: Effectively utilizing knowledge/skills and manage oneself in a manner that enhances role effectiveness and demonstrate continuous self development as specialist | D10: Effectively co-operate and properly communicate with others in responsible scope | E10: Identify, analyze issue, consider options and develop solutions to critical business process | F10: Lead/ manage team performance to drive performance in responsible scope | G10: lmprove overall performance on responsible scope and encourage others to do so by identifying and/or developing a new way forward | H10: Minimize complex risk by complying to organization's rules, practice and work standard, together with,taking preventive action | J10: - Know expected role and show responsibility as expected - Continue to acquire new knowledge, skills and expertise - Able to develop strategy and plan to drive business | K10: - Work collaboratively towards common goals - Communicate and influence effectively - Plan, inspire, coach and develop team capability | L10: - Think analytically to identify issue and solution - Make decision and implement solution over issues timely - Effectively optimize resource of department | M10: - Plan, prioritize, organize available resource and optimize process to achieve common goals - Lead self and others in achieving common goals - Inspire others as department to achieve company outcome | N10: - Generate ideas or encourage others to improve - Take action in implementing new ideas - Provide knowledge or training to others | O10: - Comply to rules and quality work standard - Identify operational risk and make prevention - Promote and monitor others in department to follow work standard, rule
A11: 8 | B11: S3E | C11: Effectively utilizing knowledge/skills and manage oneself in a manner that enhances role effectiveness and demonstrate continuous self development as specialist | D11: Effectively co-operate and properly communicate with others in responsible scope | E11: Identify, analyze issue, consider options and develop solutions to critical business process | F11: Lead/ manage team performance to drive performance in responsible scope | G11: lmprove overall performance on responsible scope and encourage others to do so by identifying and/or developing a new way forward | H11: Minimize complex risk by complying to organization's rules, practice and work standard, together with,taking preventive action | J11: - Know expected role and show responsibility as expected - Continue to acquire new knowledge, skills and expertise - Able to develop strategy and plan to drive business | K11: - Work collaboratively towards common goals - Communicate and influence effectively - Plan, inspire, coach and develop team capability | L11: - Think analytically to identify issue and solution - Make decision and implement solution over issues timely - Effectively optimize resource of department | M11: - Plan, prioritize, organize available resource and optimize process to achieve common goals - Lead self and others in achieving common goals - Inspire others as department to achieve company outcome | N11: - Generate ideas or encourage others to improve - Take action in implementing new ideas - Provide knowledge or training to others | O11: - Comply to rules and quality work standard - Identify operational risk and make prevention - Promote and monitor others in department to follow work standard, rule
A12: 9 | B12: G3E | C12: Effectively utilizing knowledge/skills and manage oneself in a manner that enhances role effectiveness and demonstrate continuous self development as specialist | D12: Effectively co-operate and properly communicate with others in responsible scope | E12: Identify, analyze issue, consider options and develop solutions to critical business process | F12: Lead/ manage team performance to drive performance in responsible scope | G12: lmprove overall performance on responsible scope and encourage others to do so by identifying and/or developing a new way forward | H12: Minimize complex risk by complying to organization's rules, practice and work standard, together with,taking preventive action | J12: - Know expected role and show responsibility as expected - Continue to acquire new knowledge, skills and expertise - Able to develop strategy and plan to drive business | K12: - Work collaboratively towards common goals - Communicate and influence effectively - Plan, inspire, coach and develop team capability | L12: - Think analytically to identify issue and solution - Make decision and implement solution over issues timely - Effectively optimize resource of department | M12: - Plan, prioritize, organize available resource and optimize process to achieve common goals - Lead self and others in achieving common goals - Inspire others as department to achieve company outcome | N12: - Generate ideas or encourage others to improve - Take action in implementing new ideas - Provide knowledge or training to others | O12: - Comply to rules and quality work standard - Identify operational risk and make prevention - Promote and monitor others in department to follow work standard, rule
A13: 10 | B13: M4E | C13: Effectively utilizing knowledge/skills and manage oneself in a manner that enhances role effectiveness and demonstrate continuous self development as management | D13: Effectively co-operate and properly communicate with others to achieve department goals | E13: Identify, analyze issue, consider options and develop solutions to correct problem in department | F13: Lead/ manage team performance to achieve resposible scope | G13: lmprove overall performance on responsible scope and encourage others to do so by identifying and/or developing a new way forward | H13: Minimize complex risk in departments / factory by complying to organization's rules, practice and work standard, together with,taking preventive action | J13: - Know expected role and show responsibility as expected - Continue to acquire new knowledge, skills and expertise - Able to develop strategy and plan to drive business | K13: - Work collaboratively towards common goals - Communicate and influence effectively - Plan, inspire, coach and develop team capability | L13: - Think analytically to identify issue and solution - Make decision and implement solution over issues timely - Effectively optimize resource of department | M13: - Plan, prioritize, organize available resource and optimize process to achieve common goals - Lead self and others in achieving common goals - Inspire others as department to achieve company outcome | N13: - Generate ideas or encourage others to improve - Take action in implementing new ideas - Provide knowledge or training to others | O13: - Comply to rules and quality work standard - Identify operational risk and make prevention - Promote and monitor others in department to follow work standard, rule
A14: 11 | B14: E4E | C14: Effectively utilizing knowledge/skills and manage oneself in a manner that enhances role effectiveness and demonstrate continuous self development as specialist | D14: Effectively co-operate and properly communicate with others in responsible scope | E14: Identify, analyze issue, consider options and develop solutions to critical business process | F14: Lead/ manage team performance to drive performance in responsible scope | G14: lmprove overall performance on responsible scope and encourage others to do so by identifying and/or developing a new way forward | H14: Minimize complex risk by complying to organization's rules, practice and work standard, together with,taking preventive action | J14: - Know expected role and show responsibility as expected - Continue to acquire new knowledge, skills and expertise - Able to develop strategy and plan to drive business | K14: - Work collaboratively towards common goals - Communicate and influence effectively - Plan, inspire, coach and develop team capability | L14: - Think analytically to identify issue and solution - Make decision and implement solution over issues timely - Effectively optimize resource of department | M14: - Plan, prioritize, organize available resource and optimize process to achieve common goals - Lead self and others in achieving common goals - Inspire others as department to achieve company outcome | N14: - Generate ideas or encourage others to improve - Take action in implementing new ideas - Provide knowledge or training to others | O14: - Comply to rules and quality work standard - Identify operational risk and make prevention - Promote and monitor others in department to follow work standard, rule
A15: 12 | B15: S4E | C15: Effectively utilizing knowledge/skills and manage oneself in a manner that enhances role effectiveness and demonstrate continuous self development as specialist | D15: Effectively co-operate and properly communicate with others in responsible scope | E15: Identify, analyze issue, consider options and develop solutions to critical business process | F15: Lead/ manage team performance to drive performance in responsible scope | G15: lmprove overall performance on responsible scope and encourage others to do so by identifying and/or developing a new way forward | H15: Minimize complex risk by complying to organization's rules, practice and work standard, together with,taking preventive action | J15: - Know expected role and show responsibility as expected - Continue to acquire new knowledge, skills and expertise - Able to develop strategy and plan to drive business | K15: - Work collaboratively towards common goals - Communicate and influence effectively - Plan, inspire, coach and develop team capability | L15: - Think analytically to identify issue and solution - Make decision and implement solution over issues timely - Effectively optimize resource of department | M15: - Plan, prioritize, organize available resource and optimize process to achieve common goals - Lead self and others in achieving common goals - Inspire others as department to achieve company outcome | N15: - Generate ideas or encourage others to improve - Take action in implementing new ideas - Provide knowledge or training to others | O15: - Comply to rules and quality work standard - Identify operational risk and make prevention - Promote and monitor others in department to follow work standard, rule
... A84: 40 | B84: P11T | C84: นำความรู้และทักษะไปใช้อย่างมีประสิทธิภาพ พัฒนาตนเองในลักษณะของการเพิ่มพูนประสิทธิภาพในบทบาทและหน้าที่ที่รับผิดชอบ และแสดงให้เห็นถึงการพัฒนาตนเองอย่างต่อเนื่องในฐานะผู้ปฏิบัติงาน | D84: ทำงานร่วมกับผู้อื่นได้อย่างมีประสิทธิภาพ รวมถึงสามารถสื่อสารเพื่อจูงใจและโน้มน้าวผู้อื่นได้อย่างเหมาะสมในฐานะผู้ปฏิบัติงาน | E84: คิดวิเคราะห์ เพื่อระบุปัญหา พร้อมกับพิจารณาทางเลือก และพัฒนาวิธีการมาแก้้ไขปัญหาในงานที่รับผิดชอบ | F84: นำตนเอง บริหารจัดการตนเองให้สามารถบรรลุเป้าหมายที่กำหนดไว้ หรือ ดำเนินงานที่ได้รับมอบหมายให้แล้วเสร็จ | G84: ปรับปรุงหน้างานประจำวันที่่รับผิดชอบ โดยการชี้บ่งวิธีการปรับปรุงุ หรือ พัฒนาแนวทางใหม่ๆ เพื่อมุ่งไปข้างหน้า | H84: ลดความเสี่ยงในกระบวนการปฏิบัติงาน โดยปรับเปลี่ยนให้สอดคล้องกับกฎระเบียบ แนวปฏิบัติ และมาตรฐานในการปฏิบัติงานของบริษัทฯ รวมไปถึงการกำหนดมาตรการป้องกัน | J84: - รู้จักบทบาทที่คาดหวังและแสดงความรับผิดชอบตามที่คาดไว้ - ดำเนินการให้ได้มาซึ่งความรู้ ทักษะ และความเชี่ยวชาญใหม่ ๆ | K84: - ทำงานร่วมกับผู้อื่นเพื่อบรรลุเป้าหมายร่วมได้ - สื่อสาร และ โน้มน้าวผู้อื่นได้อย่างมีประสิทธิภาพ | L84: - คิดเชิงวิเคราะห์เพื่อระบุปัญหา และวิธีการแก้ไข - ตัดสินใจ ภายใต้ขอบเขตของอำนาจที่ได้รับมอบหมาย และลงมือแก้ไขปัญหาตามเวลาที่กำหนด | M84: - วางแผน, จัดลำดับความสำคัญ, จัดการกับทรัพยากรที่มีอยู่ และสร้างกระบวนการทำงานที่ดีที่สุดเพื่อบรรลุเป้าหมายร่วม - นำตนเอง และผู้อื่นมุ่งสู่การบรรลุเป้าหมายร่วม | N84: - สร้างแนวคิด หรือ ส่งเสริมผู้อื่นให้ดำเนินการเรื่องการปรับปรุงงาน - นำแนวคิดไปลงมือปฏิบัติอย่างเป็นรูปธรรม | O84: - ปฏิบัติตนสอดคล้องกับกฎระเบียบ และมาตรฐานการปฏิบัติงานเพื่อให้เกิดคุณภาพ - ระบุความเสี่ยงในงาน และกำหนดมาตรการป้องกัน

Sheet New_MBO Form
A1: Thai Parkerizing Co., Ltd. | AT1: E7 | AU1: T | AV1: =AT1&AU1 -> E7T | AW1: =VLOOKUP($AV$1,'Weight & Grade Def.'!$G$7:$I$86,2,0) -> E6T | AX1: =VLOOKUP($AV$1,'Weight & Grade Def.'!$G$7:$I$86,3,0) -> E8T
A2: Performance Appraisal - Management by Objective (MBO) Form | AW2: =VLOOKUP($AV$1,'Weight & Grade Def.'!$G$7:$I$86,2,0) -> E6T | AX2: =VLOOKUP($AV$1,'Weight & Grade Def.'!$G$7:$I$86,2,0) -> E6T
AL3: Measuring Criteria : เงื่อนไขการประเมิน
A4: Name | I4: Code | M4: Position | V4: Current Grade | X4: =AT1 -> E7 | AC4: Date promoted to current grade | AL4: 5: | AM4: Far exceed expected achievement result | AW4: Upper | AX4: Lower
A5: ชื่อ-นามสกุล | I5: รหัสพนักงาน | M5: ตำแหน่ง | V5: เกรดปัจจุบัน | AC5: วันที่ได้รับการปรับสู่เกรดปัจจุบัน | AM5: ทำได้มากกว่าผลลัพธ์ที่คาดหวังไปมาก
AL6: 4: | AM6: Exceed expected achievement result
A7: Location | H7: Division / Department / Section | Z7: Date joined | AF7: Total year-of-service | AK7: Years | AM7: ทำได้มากกว่าผลลัพธ์ที่คาดหวังไว้
A8: พื้นที่ปฏิบัติงาน | H8: ฝ่าย / แผนก / หน่วยงาน | Z8: วันเริ่มงาน | AF8: อายุงาน | AL8: 3: | AM8: Fully meet expected achievement result
AM9: ทำได้ตามผลลัพธ์ที่คาดหวังไว้ทั้งหมด
A10: First Appraiser | O10: Second Appraiser | AF10: Appraisal Period | AL10: 2: | AM10: Partially meet expected achievement result
A11: (ระบุชื่อและตำแหน่งของผู้ประเมินคนที่ 1) | O11: (ระบุชื่อและตำแหน่งของผู้ประเมินคนที่ 2) | AF11: ช่วงการประเมิน | AM11: ทำได้ตามผลลัพธ์ที่คาดหวังไว้เพียงบางส่วน
AL12: 1: | AM12: Rarely meet expected achievement result
AM13: แทบจะไม่เป็นไปผลลัพธ์ที่คาดหวัง
A15: Company's Slogan 2024 คำขวัญบริษัท 2567 | F15: Let's strengthen our commitment toward sustainable growth! | AI15: Approval sign for mutual agreement on MBO (goals) below to be used in measurement ลงลายมือชื่อเพื่อแสดงความเข้าใจและตกลงร่วมกันในการนำเป้าหมายที่กำหนดไว้ด้านล่างนี้มาใช้ในการวัดผลการปฏิบัติงาน
A16: Company's Policy 2024 นโยบายบริษัท 2567 | F16: ความปลอดภัย คือ พื้นฐานของทุกสิ่ง, ปฏิบัติตามกฎหมาย และรักษา Compliance อย่างเคร่งครัด สร้างองค์กรที่ Clean, สิ่งเดียวที่จะสร้างความไว้วางใจจากลูกค้า คือ คุณภาพ, ดำเนินการแบบเชิงรุก เพื่อยกระดับประสิทธิภาพการผลิต และสร้างบริษัทที่เติบโตอย่างยั่งยืน
A18: Grade Definition คำนิยาม | C18: Upper Grade เกรดที่สูงกว่า | F18: =VLOOKUP($F$20,'Weight & Grade Def.'!$B$7:$D$46,2,0) -> E6 | G18: =IFERROR(VLOOKUP($AW$1,'Weight & Grade Def.'!$G$6:$N$86,8,0),"-") -> จัดการกับงานสำคัญที่ได้รับมอบหมายตามขอบเขตงานให้สำเร็จลุล่วงได้โดยลำพัง ; ปรับเปลี่ยน หรือ ตรวจสอบ พร้อมทั้งแก้ไขปัญหาในระบบปฏิบัติการ หรือ กระบวนการทำงานที่มีอยู่ ณ ปัจจุบัน ; แก้ไขปัญหาในการปฏิบัติงานด้วยอำนาจที่มีอยู่อย่างจำกัด เพื่อจัดการทรัพยากรการดำเนินงานในขอบเขตที่ได้รับมอบหมาย ; โน้มน้าวหรืออธิบายข้อเท็จจริง แนวปฏิบัติ นโยบาย ต่อบุคคลที่เกี่ยวข้องทั้งภายในและภายนอก ; สอนความรู้ในงานให้แก่ระดับที่ต่ำกว่า ; มีความรู้ระดับก้าวหน้าในขอบเขตงานหนึ่ง
AI19: Approval sign for mutual agreement on below performance rating ลงลายมือชื่อเพื่อแสดงถึงความเข้าใจและตกลงร่วมกันในผลของการประเมินด้านล่างนี้
C20: Current Grade เกรดปัจจุบัน | F20: =AT1 -> E7 | G20: =IFERROR(VLOOKUP($AV$1,'Weight & Grade Def.'!$G$6:$N$86,8,0),"-") -> จัดการกับงานที่ได้รับมอบหมายตามขอบเขตงานให้สำเร็จลุล่วงภายใต้การกำกับดูแลที่จำกัด ; ตรวจสอบ และ แก้ไขปัญหาในระบบปฏิบัติการ หรือ กระบวนการทำงานที่มีอยู่ ณ ปัจจุบัน ; แก้ไขปัญหาในงานที่มีการระบุไว้แล้วอย่างชัดเจนในขอบเขตที่ได้รับมอบหมาย ; อธิบายเกี่ยวกับข้อเท็จจริง แนวปฏิบัติ นโยบายแก่้ผู้มีส่วนเกี่ยวข้องหลักภายในได้ ; ให้คำชี้แนะเกี่ยวกับความรู้ในงานแก่ระดับที่ต่ำกว่า ; มีความรู้เกี่ยวกับงานในเชิงปฏิบัติในขอบเขตงานหนึ่ง
C22: Lower Grade เกรดที่ต่ำกว่า | F22: =VLOOKUP($F$20,'Weight & Grade Def.'!$B$7:$D$46,3,0) -> E8 | G22: =IFERROR(VLOOKUP($AX$1,'Weight & Grade Def.'!$G$6:$N$86,8,0),"-") -> จัดการกับงานระดับพื้นฐานที่ได้รับมอบหมายตามขอบเขตงานให้สำเร็จลุล่วงภายใต้การกำกับดูแลทั่วไป ; ตรวจสอบระบบปฏิบัติการ หรือ กระบวนการทำงานที่มีอยู่ ณ ปัจจุบัน ; แก้ไขปัญหาในงานที่มีการระบุไว้แล้วอย่างชัดเจนในขอบเขตที่ได้รับมอบหมาย ; อธิบายเกี่ยวกับข้อเท็จจริง แนวการปฏิบัติ นโยบายแก่้ผู้มีส่วนเกี่ยวข้องหลักภายในได้ ; ให้คำชี้แนะเกี่ยวกับความรู้ในงานแก่ระดับที่ต่ำกว่า ; มีความรู้เกี่ยวกับงานในเชิงทฤษฎีในขอบเขตงานหนึ่ง
A26: Part 1 : Initial & Improvement (Total weight for Part 1 must be | K26: =VLOOKUP($AT$1,'Weight & Grade Def.'!$B$7:$M$46,10,0) -> 60 | L26: %
A28: No. ลำดับ | B28: Goal : Quatitative / Qualitative (What are you expected to achieve?) เป้าหมาย : ทั้งเชิงปริมาณและเชิงคุณภาพ (สิ่งที่คุณถูกคาดหวังให้ดำเนินการจนสำเร็จ) | F28: 1st-Half Assessment for Mid-Year Bonus (การประเมินผลช่วงครึ่งปีแรก ม.ค. ถึง มิ.ย. เพื่อจ่ายโบนัสกลางปี) | Z28: 2nd-Half Assessment for Year-End Bonus (การประเมินผลช่วงครึ่งปีหลัง ก.ค. ถึง ธ.ค. เพื่อจ่ายโบนัสปลายปี)
F29: Action Plan : แผนปฏิบัติงาน (required process, schedule for goal realization กระบวนการที่จำเป็น, กำหนดการเพื่อให้เป้าหมายประสบผลสำเร็จ) | I29: Start-End วันที่เริ่มต้นและสิ้นสุด | J29: Achievement measuing criteria (i.e. what and how for each rating) ตัวชี้วัดความสำเร็จ (คือ วัดด้วยสิ่งใด และจะวัดอย่างไร) | M29: Status review of each objective at mid-term (Appraiser & Appraisee discuss results) ทบทวนความสำเร็จของแต่ละเป้าหมาย ในช่วงกลางปี (ผู้ประเมินและผู้ถูกประเมินพูดคุยกันเกี่ยวกับผลลัพธ์ที่เกิดขึ้น) | P29: Weight (%) น้ำหนัก | Q29: Self-Assessment () | T29: 1st Appraisal Assessment () | W29: 2nd Appraisal Assessment () | Z29: Action Plan : แผนปฏิบัติงาน (required process, schedule for goal realization กระบวนการที่จำเป็น, กำหนดการเพื่อให้เป้าหมายประสบผลสำเร็จ) | AC29: Start-End วันที่เริ่มต้นและสิ้นสุด | AD29: Achievement measuing criteria (i.e. what and how for each rating) ตัวชี้วัดความสำเร็จ (คือ วัดด้วยสิ่งใด และจะวัดอย่างไร) | AG29: Status review of each objective at mid-term (Appraiser & Appraisee discuss results) ทบทวนความสำเร็จของแต่ละเป้าหมาย ในช่วงกลางปี (ผู้ประเมินและผู้ถูกประเมินพูดคุยกันเกี่ยวกับผลลัพธ์ที่เกิดขึ้น) | AJ29: Weight (%) น้ำหนัก | AK29: Self-Assessment () | AN29: 1st Appraisal Assessment () | AQ29: 2nd Appraisal Assessment ()
Q30: Score | R30: Achieved numeric value / condition ระบุตัวเลข / ลักษณะ ที่บอกถึงความสำเร็จตามเป้าหมาย | T30: Score | U30: Achieved numeric value / condition ระบุตัวเลข / ลักษณะ ที่บอกถึงความสำเร็จตามเป้าหมาย | W30: Score | X30: Achieved numeric value / condition ระบุตัวเลข / ลักษณะ ที่บอกถึงความสำเร็จตามเป้าหมาย | AK30: Score | AL30: Achieved numeric value / condition ระบุตัวเลข / ลักษณะ ที่บอกถึงความสำเร็จตามเป้าหมาย | AN30: Score | AO30: Achieved numeric value / condition ระบุตัวเลข / ลักษณะ ที่บอกถึงความสำเร็จตามเป้าหมาย | AQ30: Score | AR30: Achieved numeric value / condition ระบุตัวเลข / ลักษณะ ที่บอกถึงความสำเร็จตามเป้าหมาย
Q31: คะแนน | T31: คะแนน | W31: คะแนน | AK31: คะแนน | AN31: คะแนน | AQ31: คะแนน
A32: MBO (Goal) : 1
A38: MBO (Goal) : 2
A44: MBO (Goal) : 3
A50: MBO (Goal) : 4
A56: MBO (Goal) : 5
A62: MBO (Goal) : 6
A68: MBO (Goal) : 7
M74: Sub Total | P74: =SUM($P$32:$P$73) -> 0 | Q74: =($P32*Q32)+($P38*Q38)+($P44*Q44)+($P50*Q50)+($P56*Q56)+($P62*Q62)+($P68*Q68) -> 0 | T74: =($P32*T32)+($P38*T38)+($P44*T44)+($P50*T50)+($P56*T56)+($P62*T62)+($P68*T68) -> 0 | W74: =($P32*W32)+($P38*W38)+($P44*W44)+($P50*W50)+($P56*W56)+($P62*W62)+($P68*W68) -> 0 | AG74: Sub Total | AJ74: =SUM(AJ32:AJ73) -> 0 | AK74: =($AJ32*AK32)+($AJ38*AK38)+($AJ44*AK44)+($AJ50*AK50)+($AJ56*AK56)+($AJ62*AK62)+($AJ68*AK68) -> 0 | AN74: =($AJ32*AN32)+($AJ38*AN38)+($AJ44*AN44)+($AJ50*AN50)+($AJ56*AN56)+($AJ62*AN62)+($AJ68*AN68) -> 0 | AQ74: =($AJ32*AQ32)+($AJ38*AQ38)+($AJ44*AQ44)+($AJ50*AQ50)+($AJ56*AQ56)+($AJ62*AQ62)+($AJ68*AQ68) -> 0
A77: Part 2 : Regular Work (Total weight for Part 2 must be | J77: =VLOOKUP($AT$1,'Weight & Grade Def.'!$B$7:$M$46,11,0) -> 40 | K77: %
A79: No. ลำดับ | B79: Goal : Quatitative / Qualitative (What are you expected to achieve?) เป้าหมาย : ทั้งเชิงปริมาณและเชิงคุณภาพ (สิ่งที่คุณถูกคาดหวังให้ดำเนินการจนสำเร็จ) | F79: 1st-Half Assessment for Mid-Year Bonus (การประเมินผลช่วงครึ่งปีแรก ม.ค. ถึง มิ.ย. เพื่อจ่ายโบนัสกลางปี) | Z79: 2nd-Half Assessment for Year-End Bonus (การประเมินผลช่วงครึ่งปีหลัง ก.ค. ถึง ธ.ค. เพื่อจ่ายโบนัสปลายปี)
F80: Action Plan : แผนปฏิบัติงาน (required process, schedule for goal realization กระบวนการที่จำเป็น, กำหนดการเพื่อให้เป้าหมายประสบผลสำเร็จ) | I80: Start-End วันที่เริ่มต้นและสิ้นสุด | J80: Achievement measuing criteria (i.e. what and how for each rating) ตัวชี้วัดความสำเร็จ (คือ วัดด้วยสิ่งใด และจะวัดอย่างไร) | M80: Status review of each objective at mid-term (Appraiser & Appraisee discuss results) ทบทวนความสำเร็จของแต่ละเป้าหมาย ในช่วงกลางปี (ผู้ประเมินและผู้ถูกประเมินพูดคุยกันเกี่ยวกับผลลัพธ์ที่เกิดขึ้น) | P80: Weight (%) น้ำหนัก | Q80: Self-Assessment () | T80: 1st Appraisal Assessment () | W80: 2nd Appraisal Assessment () | Z80: Action Plan : แผนปฏิบัติงาน (required process, schedule for goal realization กระบวนการที่จำเป็น, กำหนดการเพื่อให้เป้าหมายประสบผลสำเร็จ) | AC80: Start-End วันที่เริ่มต้นและสิ้นสุด | AD80: Achievement measuing criteria (i.e. what and how for each rating) ตัวชี้วัดความสำเร็จ (คือ วัดด้วยสิ่งใด และจะวัดอย่างไร) | AG80: Status review of each objective at mid-term (Appraiser & Appraisee discuss results) ทบทวนความสำเร็จของแต่ละเป้าหมาย ในช่วงกลางปี (ผู้ประเมินและผู้ถูกประเมินพูดคุยกันเกี่ยวกับผลลัพธ์ที่เกิดขึ้น) | AJ80: Weight (%) น้ำหนัก | AK80: Self-Assessment () | AN80: 1st Appraisal Assessment () | AQ80: 2nd Appraisal Assessment ()
Q81: Score | R81: Achieved numeric value / condition ระบุตัวเลข / ลักษณะ ที่บอกถึงความสำเร็จตามเป้าหมาย | T81: Score | U81: Achieved numeric value / condition ระบุตัวเลข / ลักษณะ ที่บอกถึงความสำเร็จตามเป้าหมาย | W81: Score | X81: Achieved numeric value / condition ระบุตัวเลข / ลักษณะ ที่บอกถึงความสำเร็จตามเป้าหมาย | AK81: Score | AL81: Achieved numeric value / condition ระบุตัวเลข / ลักษณะ ที่บอกถึงความสำเร็จตามเป้าหมาย | AN81: Score | AO81: Achieved numeric value / condition ระบุตัวเลข / ลักษณะ ที่บอกถึงความสำเร็จตามเป้าหมาย | AQ81: Score | AR81: Achieved numeric value / condition ระบุตัวเลข / ลักษณะ ที่บอกถึงความสำเร็จตามเป้าหมาย
Q82: คะแนน | T82: คะแนน | W82: คะแนน | AK82: คะแนน | AN82: คะแนน | AQ82: คะแนน
A83: MBO (Goal) : 1
A89: MBO (Goal) : 2
A95: MBO (Goal) : 3
...

Sheet Weight & Grade Def.
G1: 1 | H1: 2 | I1: 3 | J1: 4 | K1: 5 | L1: 6 | M1: 7 | N1: 8
B2: 1 | C2: 2 | D2: 3 | E2: 4 | F2: 5 | G2: 6 | H2: 7 | I2: 8 | J2: 9 | K2: 10 | L2: 11 | M2: 12 | N2: 13 | O2: 14 | P2: 15 | Q2: 16 | R2: 17 | S2: 18 | T2: 19 | U2: 20 | V2: 21 | W2: 22 | X2: 23 | Y2: 24
B4: Current Grade | C4: Upper | D4: Lower | G4: Current Grade | H4: Upper | I4: Lower | J4: Total MBO | K4: MBO (Initiative) | L4: MBO Regular | M4: 6 Factors | N4: Link | O4: Position title | P4: Role | W4: Formula to integrate grade definition | X4: For appraisal sheet (vlookup) | Y4: For appraisal sheet (vlookup)
Q5: Out put | R5: Process | V5: Input
Q6: Accountability | R6: Creating value | S6: Solving problem | T6: Communicating with others | U6: Developing people | V6: Knowleadege
B7: M1 | C7: - | D7: M2 | E7: E | F7: T | G7: =B7&E7 -> M1E | H7: - | I7: =D7&E7 -> M2E | J7: 70 | K7: 70 | L7: 30 | M7: 30 | N7: -Co-develops mid to long-term (3-5 years) strategy and manages divisions for achieving the company’s goals - Significantly improves or adapts existing processes/systems/products that impact to divisions,Solves multi-dimensional business issues with authority to manage operational resources, human resources and financial resources over divisions, Convinces internal and external parties who might have divergent view to accept company’s policy, Coaches Division managers and grooms successors - Has broad and substantive management knowledge across several divisions and skills for managing managers | O7: Vice President | P7: Management level | Q7: Co-develops mid to long-term (3-5 years) strategy and manages divisions for achieving the company’s goals | R7: Significantly improves or adapts existing processes/systems/products that impact to divisions | S7: Solves multi-dimensional business issues with authority to manage operational resources, human resources and financial resources over divisions | T7: Convinces internal and external parties who might have divergent view to accept company’s policy | U7: Coaches Division managers and grooms successors | V7: Has broad and substantive management knowledge across several divisions and skills for managing managers | W7: =Q7&R7&S7&T7&U7&V7 -> Co-develops mid to long-term (3-5 years) strategy and manages divisions for achieving the company’s goals Significantly improves or adapts existing processes/systems/products that impact to divisions Solves multi-dimensional business issues with authority to manage operational resources, human resources and financial resources over divisions Convinces internal and external parties who might have divergent view to accept company’s policy Coaches Division managers and grooms successors Has broad and substantive management knowledge across several divisions and skills for managing managers | X7: -Co-develops mid to long-term (3-5 years) strategy and manages divisions for achieving the company’s goals - Significantly improves or adapts existing processes/systems/products that impact to divisions,Solves multi-dimensional business issues with authority to manage operational resources, human resources and financial resources over divisions, Convinces internal and external parties who might have divergent view to accept company’s policy, Coaches Division managers and grooms successors - Has broad and substantive management knowledge across several divisions and skills for managing managers | Y7: ร่วมกำหนดแผนกลยุทธ์ระยะกลางถึงระยะยาว (3-5 ปี) และบริหารจัดการความสำเร็จของทุกๆ ฝ่ายงาน เพื่อให้บรรลุเป้าหมายของบริษัทฯ ; ดำเนินการปรับปรุง หรือ เปลี่ยนแปลงอย่างมีนัยสำคัญใน กระบวนการ / ระบบ / ผลิตภัณฑ์ ณ ปัจจุบัน ที่จะส่งผลกระทบต่อฝ่ายงานต่างๆ ; จัดการปัญหาในหลายมิติด้วยอำนาจตามบทบาทและหน้าที่ เพื่อบริหารจัดการทรัพยากรในการดำเนินงาน ทรัพยากรบุคคล และการเงินของทุกฝ่ายงาน ; โน้มน้าวบุคคลทั้งภายในและภายนอกที่เห็นต่างให้เต็มใจยอมรับนโยบายของบริษัทฯ ; พัฒนา M2 (Division Managers) ให้สามารถคิด และลงมือทำได้ด้วยตนเอง พร้อมกับสร้างผู้สืบทอดตำแหน่งไปพร้อมๆ กัน ; มีความรู้ด้านการบริหารจัดการในเชิงกว้างและมากพอ ครอบคลุมทุกฝ่ายงาน และมีทักษะในการกำกับดูแลกลุ่มผู้จัดการทั้งหมด
B8: M2 | C8: M1 | D8: M3 | E8: E | F8: T | G8: =B8&E8 -> M2E | H8: =C8&E8 -> M1E | I8: =D8&E8 -> M3E | J8: 60 | K8: 70 | L8: 30 | M8: 40 | N8: -Develops short to mid-term (1-3 years) strategy and manages the division for achieving the division’s goals - Significantly improves or adapts existing processes/systems/products that impact to the division, Solves complex business issues with authority to manage operational resources and limited human or financial resources over the division, Convinces internal and external parties who might have divergent view to accept division’s policy, Coaches Senior managers and grooms successors - Has broad knowledge of all job areas within the division and skills for managing managers | O8: Division Manager | P8: Management level | Q8: Develops short to mid-term (1-3 years) strategy and manages the division for achieving the division’s goals | R8: Significantly improves or adapts existing processes/systems/products that impact to the division | S8: Solves complex business issues with authority to manage operational resources and limited human or financial resources over the division | T8: Convinces internal and external parties who might have divergent view to accept division’s policy | U8: Coaches Senior managers and grooms successors | V8: Has broad knowledge of all job areas within the division and skills for managing managers | W8: =Q8&R8&S8&T8&U8&V8 -> Develops short to mid-term (1-3 years) strategy and manages the division for achieving the division’s goals Significantly improves or adapts existing processes/systems/products that impact to the division Solves complex business issues with authority to manage operational resources and limited human or financial resources over the division Convinces internal and external parties who might have divergent view to accept division’s policy Coaches Senior managers and grooms successors Has broad knowledge of all job areas within the division and skills for managing managers | X8: -Develops short to mid-term (1-3 years) strategy and manages the division for achieving the division’s goals - Significantly improves or adapts existing processes/systems/products that impact to the division, Solves complex business issues with authority to manage operational resources and limited human or financial resources over the division, Convinces internal and external parties who might have divergent view to accept division’s policy, Coaches Senior managers and grooms successors - Has broad knowledge of all job areas within the division and skills for managing managers | Y8: จัดทำแผนกลยุทธ์ระยะสั้นถึงระยะกลาง (1-3ปี) และบริหารจัดการการบรรลุผลสำเร็จตามเป้าหมายของฝ่ายงานที่รับผิดชอบ ; ปรับปรุง เปลี่ยนแปลงอย่างมีนัยสำคัญใน กระบวนการ / ระบบ / ผลิตภัณฑ์ ทีมีอยู่ณ ปัจจุบัน ที่จะส่งผลกระทบต่อฝ่ายงานที่รับผิดชอบ ; จัดการปัญหาทางธุรกิจที่ซับซ้อนมากขึ้นด้วยอำนาจตามบทบาทและหน้าที่ เพื่อบริหารทรัพยากรในการดำเนินงาน รวมถึงบุคลากร และการเงินของฝ่ายงานที่รับผิดชอบซึ่งมีอยู่จำกัด ; โน้มน้าวบุคคลทั้งภายในและภายนอกที่เห็นต่างให้เต็มใจยอมรับนโยบายของฝ่าย ; พัฒนา M3 หรือ Senior Manager ให้สามารถคิด และลงมือทำได้ด้วยตนเอง พร้อมกับสร้างผู้สืบทอดตำแหน่งไปพร้อมๆ กัน ; มีความรู้ในเชิงกว้างครอบคลุมทุกส่วนในฝ่ายงานที่รับผิดชอบ และมีทักษะในการกำกับดูแลกลุ่มผู้จัดการ
B9: E2 | C9: M1 | D9: E3 | E9: E | F9: T | G9: =B9&E9 -> E2E | H9: =C9&E9 -> M1E | I9: =D9&E9 -> E3E | J9: 60 | K9: 70 | L9: 30 | M9: 40 | N9: - Manages large initiatives that create significant value to entire company’s operation for achieving critical initiative’s goals - Enhances existing processes/systems/products for level up company performance, Solves business issues with some authorities to manage operational resources and limited human or financial resources related the initiatives, Convinces internal and external parties who might have divergent view to accept the initiative policy, Coaches and shares knowledge with others - Has advanced and well-developed job knowledge for assigned project operating and skills for managing team members | O9: Expert | P9: Specialist | Q9: Manages large initiatives that create significant value to entire company’s operation for achieving critical initiative’s goals | R9: Enhances existing processes/systems/products for level up company performance | S9: Solves business issues with some authorities to manage operational resources and limited human or financial resources related the initiatives | T9: Convinces internal and external parties who might have divergent view to accept the initiative policy | U9: Coaches and shares knowledge with others | V9: Has advanced and well-developed job knowledge for assigned project operating and skills for managing team members | W9: =Q9&R9&S9&T9&U9&V9 -> Manages large initiatives that create significant value to entire company’s operation for achieving critical initiative’s goals Enhances existing processes/systems/products for level up company performance Solves business issues with some authorities to manage operational resources and limited human or financial resources related the initiatives Convinces internal and external parties who might have divergent view to accept the initiative policy Coaches and shares knowledge with others Has advanced and well-developed job knowledge for assigned project operating and skills for managing team members | X9: - Manages large initiatives that create significant value to entire company’s operation for achieving critical initiative’s goals - Enhances existing processes/systems/products for level up company performance, Solves business issues with some authorities to manage operational resources and limited human or financial resources related the initiatives, Convinces internal and external parties who might have divergent view to accept the initiative policy, Coaches and shares knowledge with others - Has advanced and well-developed job knowledge for assigned project operating and skills for managing team members | Y9: บริหารโครงการริเริ่มขนาดใหญ่ ที่จะสร้างคุณค่า หรือเป็นประโยชน์อย่างมีนัยสำคัญต่อการดำเนินงานของบริษัทฯ ในภาพรวม เพื่อให้บรรลุผลสำเร็จตามเป้าหมายสำคัญที่โครงการกำหนดไว้ ; เพิ่มระดับความสำเร็จของกระบวนการ / ระบบ / ผลิตภัณฑ์ที่มีอยู่ เพื่อยกระดับผลการดำเนินงานขององค์กรให้ดีขึ้น ; จัดการปัญหาทางธุรกิจ ด้วยอำนาจเท่าที่ได้รับมอบหมาย เพื่อบริหารทรัพยากรในการดำเนินงาน, รวมถึงทรัพยากรบุคคลากร หรือการเงินของโครงการที่ริเริ่มนั้นๆ ซึ่งมีอยู่จำกัด ; โน้มน้าวบุคคลภายในและภายนอกที่มีความเห็นต่างให้เกิดการยอมรับในนโยบายของโครงการที่ริเริ่มนั้นๆ ; แบ่งปันความรู้ และพัฒนาผู้อื่นให้สามารถคิดและดำเนินการได้ด้วยตนเอง ; มีความรู้ที่ได้รับการพัฒนามาเป็นอย่างดีและเป็นความรู้ระดับก้าวหน้าเพื่อบริหารจัดการโครงการที่ได้รับมอบหมาย และมีทักษะในการจัดการสมาชิกในทีม
B10: S2 | C10: M1 | D10: S3 | E10: E | F10: T | G10: =B10&E10 -> S2E | H10: =C10&E10 -> M1E | I10: =D10&E10 -> S3E | J10: 60 | K10: 70 | L10: 30 | M10: 40 | N10: - Manages large initiatives that create significant value to entire company’s operation for achieving critical initiative’s goals - Enhances existing processes/systems/products for level up company performance, Solves business issues with some authorities to manage operational resources and limited human or financial resources related the initiatives, Convinces internal and external parties who might have divergent view to accept the initiative policy, Coaches and shares knowledge with others - Has advanced and well-developed job knowledge for assigned project operating and skills for managing team members | O10: Expert | P10: Specialist | Q10: Manages large initiatives that create significant value to entire company’s operation for achieving critical initiative’s goals | R10: Enhances existing processes/systems/products for level up company performance | S10: Solves business issues with some authorities to manage operational resources and limited human or financial resources related the initiatives | T10: Convinces internal and external parties who might have divergent view to accept the initiative policy | U10: Coaches and shares knowledge with others | V10: Has advanced and well-developed job knowledge for assigned project operating and skills for managing team members | W10: =Q10&R10&S10&T10&U10&V10 -> Manages large initiatives that create significant value to entire company’s operation for achieving critical initiative’s goals Enhances existing processes/systems/products for level up company performance Solves business issues with some authorities to manage operational resources and limited human or financial resources related the initiatives Convinces internal and external parties who might have divergent view to accept the initiative policy Coaches and shares knowledge with others Has advanced and well-developed job knowledge for assigned project operating and skills for managing team members | X10: - Manages large initiatives that create significant value to entire company’s operation for achieving critical initiative’s goals - Enhances existing processes/systems/products for level up company performance, Solves business issues with some authorities to manage operational resources and limited human or financial resources related the initiatives, Convinces internal and external parties who might have divergent view to accept the initiative policy, Coaches and shares knowledge with others - Has advanced and well-developed job knowledge for assigned project operating and skills for managing team members | Y10: บริหารโครงการริเริ่มขนาดใหญ่ ที่จะสร้างคุณค่า หรือเป็นประโยชน์อย่างมีนัยสำคัญต่อการดำเนินงานของบริษัทฯ ในภาพรวม เพื่อให้บรรลุผลสำเร็จตามเป้าหมายสำคัญที่โครงการกำหนดไว้ ; เพิ่มระดับความสำเร็จของกระบวนการ / ระบบ / ผลิตภัณฑ์ที่มีอยู่ เพื่อยกระดับผลการดำเนินงานขององค์กรให้ดีขึ้น ; จัดการปัญหาทางธุรกิจ ด้วยอำนาจเท่าที่ได้รับมอบหมาย เพื่อบริหารทรัพยากรในการดำเนินงาน, รวมถึงทรัพยากรบุคคลากร หรือการเงินของโครงการที่ริเริ่มนั้นๆ ซึ่งมีอยู่จำกัด ; โน้มน้าวบุคคลภายในและภายนอกที่มีความเห็นต่างให้เกิดการยอมรับในนโยบายของโครงการที่ริเริ่มนั้นๆ ; แบ่งปันความรู้ และพัฒนาผู้อื่นให้สามารถคิดและดำเนินการได้ด้วยตนเอง ; มีความรู้ที่ได้รับการพัฒนามาเป็นอย่างดีและเป็นความรู้ระดับก้าวหน้าเพื่อบริหารจัดการโครงการที่ได้รับมอบหมาย และมีทักษะในการจัดการสมาชิกในทีม
